---
title: 协程取消
tag: Kotlin
---

> 协程的任务取消需要协程内部调用的协作支持，类似于线程中断中对中断状态的响应一样

## 线程的中断

当我们执行一个任务时,很快就后悔了,怎么办?

```kotlin
val thread = thread {
    try {
        Thread.sleep(1000)
    } catch(e :Exception) {
        log("interrupted, do cleaning stuff")
    }
}
thread.interrupt()
```

当线程被标记为中断状态,就会抛出 `InterruptedException` ,我们可以进行捕获做资源清理.

所以,所谓的协作式任务种植,协程的取消也是`cancel`机制的设计思路.

## 协程的取消

```kotlin
fun main()= runBlocking {
    val job1 = launch{
        log(1)
        delay(1000)
        log(2)
    }
    
    delay(100)
    log(3)
    job1.cancel()
    log(4)
}
```

`delay` 与线程中的 `sleep ` 不同,它不会阻塞线程,可以认为它实际上就是触发了一个延时任务,告诉协程调度系统 1000ms  后再来执行后面的代码;而再这期间,我们对刚刚启动的协程进行了取消,因此 `delay` 还没有回调的时候,协程就被取消了,因为 `delay` 可以影响取消,因此 `delay` 后面的代码就不会再次调度,直接抛出一个 `CancellationException`

**完善前面的一个例子**

```kotlin
suspend fun getUserCoroutine() = suspendCoroutine<User> {continuation -> 
	getUser(object: Callback<User>{
        override fun onSuccess(value: String) {
            continuation.resume(value)
        }
        
        override fun onFailed(e:Throwable) {
            continuation.resumeWithException(e)
        }
    })
}
```

加上取消逻辑

```kotlin
suspend fun getUserCoroutine() = suspendCancellableCoroutine<User> { continuation-> 
	val call = OkHttpClient().newCall(...)
    continuation.invokeOnCancellation{
		log()
         call.cancel()
	}
 	call.enqueue(object : okhttp3.Callback{
        override fun onFailure(call: Call, e: Exception) {
            log("onFailure: $e")
            continuation.resumeWithException(e)
        }
        
        override fun onResponse(call: Call, response: Response) {
            log("onResponse: ${response.code()}")
            response.body()?.let {
                try {
                    continuation.resume(User.from(it.string()))
                } catch(e: Exception) {
                    continuation.resumeWithException(e)
                }
            } ?: continuation.resumeWithException(NullPointerException("ResponseBody is null"))
        }
    })
}
```

`suspendCancellableCoroutine`  是为了让我们的挂起函数支持协程的取消.该方法将获取到的`Continuation` 包装成了一个`CacncellableContinuation` 通过调用 `invokeOnCancellation` 方法可以设置一个取消时间的回调,一旦被调用,意味着 `getUserCoroutine` 调用所在的协程将被取消,我们也应该相应的做出取消操作.

```kotlin
val job1 = launch {
    log(1)
    val user = getUserCoroutine()
    log(user)
    log(2)
}

delayt(10)
log(3)
job1.cancel()
log(4)
```

```tex
1
3
invokeOnCancellation: cancel the request.
4
onFilure: java.io.IOException: Canceled
```

取消的回调被调用了, OkHttp 在收到我们的取消指令之后,也确实停止了网络请求,并且给我们一个 IO 异常.此时,我们的协程已经取消,在处于取消状态的携程上调用`continuation.resume` `continuation.resumeWithException` `continuation.resumtWith`  都会被忽略,因此 OkHttp 回调中我们收到 IO 异常后,调用的 `continuation.resumeWithException(e)`  不会有任何副作用.

