---
title: 协程异常处理
tag: Kotlin
---

1. **协程内部异常处理流程**： 

   `launch` 会在内部出现未捕获的异常时尝试触发对父协程的取消，能否取消要看其作用域的定义，如果取消成功，那么异常传递给其父协程，否则传递给启动时上下文配置的 `CoroutineExceptionHandler` 中，如果没有配置，会查找全局（JVM）上的`CoroutineExceptionHandler` 处理，

    `async` 在未捕获异常的出现时同样会尝试取消其父协程，但不管是否能够取消成功都不会进行后续的异常处理，直到用户主动调用 `await` 时抛出

2. **异常在作用域内传播**

   当协程出现异常时，会根据当前作用域触发异常传递

   `GlobalScope` 会创建一个独立的作用域，**自成一派**

   `coroutineScope`  当中的协程异常会触发父协程的取消，将整个协程作用域取消掉，如果对 `coroutineScope` 整体进行捕获，也可以捕获到该异常，**一损俱损**

   `supervisorScope` 子协程的异常不会向上传递， **自作自受**

3. **join** 和 **await**

   `join `  只关心是否执行完， `await ` 则关心运行的结果

   因此 `join` 在协程出现异常时也不会抛出该异常，而 `await` 则会直接抛出异常；

   **Note:** 考虑到作用域的问题，如果协程抛出异常，可能导致父协程的取消，因此调用 `join` 时，尽管不会对协程本身的异常进行抛出，但如果 `join` 调用所在的协程被取消，就会抛出 *取消异常*



当我们进行异步请求时，必然会有失败的情况发生，那么我们继续上一个例子完善它

```kotlin
interface Callback<T> {
    fun onSuccess(value: T)
    fun onError(t: Throwable)
}

fun getUser(callback: Callback){}
suspend fun getUserCoroutine() = suspendCoroutine<User> {continuation->
	getUser(object: Callback<User> {
        override fun onSuccess(user: User) {
            continuation.resume(resume)
        } 
        
        override fun onError(e: Throwable) {
            continuation.resumeWithException(t)
        }
    })                                                        
}

GlobalScope.launch(Dispatchers.Main) {
    try {
        userNameView.text = getUserCoroutine().name
    } catch(e:Exception) {
        userNameView.text = "Get user error: $e"
    }
}
```

## 全局异常处理

线程也好，RxJava 也好，都会有全局处理异常的方式

```kotlin
fun main(){
    Thread.setDefaultUncaughtExceptionHandler{t: Thread, e: Throwable ->
    	// handle exception here
		println("Thread '${t.name}' throws an exception with mesage '${e.message}'")
	}
    throw ArithmeticException("Hey!")
}
```

RxJava 设置全局异常捕获

```java
RxJavaPlugins.setErrorHandler(e-> {
    println("Throws an exception with message '${e.message}'")
})
```

**协程也可以设置**，类似于通过 `Thread.setUnCaughtExceptionHandler` 为线程设置一个异常捕获器，同时也可以为每一个协程单独设置 `CoroutineExceptionHandler` 这样协程内未捕获的异常既可以通过它来捕获

```kotlin
private suspend fun main(){
    val exceptionHandler = CoroutineExceptionHandler{ coroutineContext, throwable -> 
		println("Throws an exception with message: '${throwable.message}'")
	}
    
    GlobalScope.launch(exceptionHandler) {
        throw ArithemticException("Hey!")
    }.join()
}
```

`ConroutineExceptionHandler` 也是一个上下文。当然上面的只能捕获对应协程内未捕获的异常，真正的全局捕获，在JVM上我们可以自己定义一个实现

```kotlin
class GlobalCoroutineExceptionHandler: CoroutineExceptionHandler {
    override val key: CoroutineContext.Key<*> = CoroutineExceptinHandler
    
    override fun handleException(context, CoroutineContext, exception: Throwable) {
        println("coroutine exceptino: $exception")
    }
}
```

然后在 `classpath` 中创建 `META-INFO/services/kotlinx.coroutines.CoroutineExceptionHandler` 的全类名，文件内容就写我们的实现类的全名

```tex
com.***.***.exceptions.GlobalCoroutineExceptionHandler
```

## 异常传播

### 协程作用域

当我们启动协程的时候，一直都在用 `GlobalScope` ，意味着这是要给独立的顶级协程作用域，此外还有`coroutineScope{}` 及 `supervisorScope{}`

* 通过 `GlobalScope` 启动的协程单独启动一个协程作用域，内部的子协程遵循默认的作用域规则。通过 `GlobalScope` 启动的协程自成一派
* `coroutineScope` 是继承外部 `Job` 的上下文创建作用域，在其内部的取消操作是双向传播的，子协程未捕获的异常会向上传递给它的父协程。它更适合一系列对等的协程并发的完成一项工作，**任何一个子协程异常退出，那么整体都将退出**， **一损俱损** ，同时这也是协程内部再启动子协程的默认作用域
* `supervisorScope` 同样继承外部作用域的上下文，但其内部的取消操作是单项传播的，父协程向子协程传播，反过来不行。意味着**子协程出现了异常并不会影响父协程以及其他兄弟协程**，它更适合一些独立不相干的任务，任何一个任务出问题，并不会影响其他任务的工作，**自作自受**。`supervisorScope` 内部启动的子协程再启动子协程，如无明确指出，则遵循默认作用域规则，**即`supervosorScope` 只作用其直接子协程**

```kotlin
suspend fun main (){
    log(1)
    try {
        coroutineScope {
            log(2)
            launch {
                log(3)
                launch {
                    log(4)
                    delay(100)
                    throw ArithmeticException("Hello")
                }
                log(5)
            }
            log(6)
            val job = launch {
                log(7)
                delay(1000)
            }
            try {
                log(8)
                job.join()
                log(9)
            } catch (e: Exception) {
                log("10 $e")
            }
        }
        log(11)
    } catch (e: Exception) {
        log("12 $e")
    }
    log(13)
}
```

```tex
1
2
6
3
5
4
8
7
10 kotlinx.coroutines.JobCancellationException: ScopeCoroutine is cancelling; job=ScopeCoroutine{Cancelling}@695fd68b
12 java.lang.ArithmeticException: Hello
13
```

从上面的程序和结果我们可以看出，**10**  这里，我们调用 `join` 收到了一个取消异常，在协程当中支持取消的操作的 `suspend` 函数在取消是抛出一个 `CancellationException`。

协程 3 抛出了，未捕获异常，进入异常完成状态，它与父协程 2 之间遵循默认的作用域规则，因此 3 会通知它的父协程取消， 2 根据作用域规则通知父协程 1 ，也就是整个作用域取消，自下向上传播。在 1 中的 `job.join()` 调用就会抛出异常，也就是 10 出的结果。最终由 3 抛出的异常在 12 出被捕获。

我们将 `coroutineScope` 换成 `supervisorScope` ，其他不变

```tex
1
2
6
3
5
4
8
7
Exception in thread "DefaultDispatcher-worker-3" java.lang.ArithmeticException: Hello
	at com.hachi.common.GlobalExceptionHandlerKt$main$2$1$1.invokeSuspend(GlobalExceptionHandler.kt:69)
	at kotlin.coroutines.jvm.internal.BaseContinuationImpl.resumeWith(ContinuationImpl.kt:33)
	at kotlinx.coroutines.DispatchedTask.run(Dispatched.kt:241)
	at kotlinx.coroutines.scheduling.CoroutineScheduler.runSafely(CoroutineScheduler.kt:594)
	at kotlinx.coroutines.scheduling.CoroutineScheduler.access$runSafely(CoroutineScheduler.kt:60)
	at kotlinx.coroutines.scheduling.CoroutineScheduler$Worker.run(CoroutineScheduler.kt:740)
9
11
13
```

我们可以看出，1-8 的输出没有区别，顺序上的差异是线程调度造成的，并不会影响协程的语义。

我们为内部协程增加啊一个 `CoroutineExceptionHandler` 就可以证明我们一个结论

```kotlin
val exceptionHandler = CoroutineExceptioHandler {coroutineContext, throwable -> 
           log("${coroutineContext[CoroutineName]} $throwable")                                     }
```

```kotlin
suspend fun main (){
    log(1)
    try {
        superisorScope {
            log(2)
            launch(exceptionHandler + CoroutineName("2")) {
                log(3)
                launch (exceptionHandler + CoroutineName("3")){
                    log(4)
                    delay(100)
                    throw ArithmeticException("Hello")
                }
                log(5)
            }
            log(6)
            val job = launch {
                log(7)
                delay(1000)
            }
            try {
                log(8)
                job.join()
                log(9)
            } catch (e: Exception) {
                log("10 $e")
            }
        }
        log(11)
    } catch (e: Exception) {
        log("12 $e")
    }
    log(13)
}
```

```tex
1
2
6
3
5
4
8
7
CoroutineName(2) java.lang.ArithmeticException: Hello
9
11
13
```

我们看到，触发`CoroutineExceptionHandler` 的是协程 2。

### 如何使用 scope

* 对于没有协程作用域，但需要启动协程的时候，适合用 **GlobalScope**
* 对于已经由协程作用域的情况，直接用协程启动器启动
* 对于明确要求子协程之间互相独立不干扰时，使用 **supervisorScope**
* 对于通过标准库 API 创建的协程，这样的协程比较底层，没有 `Job` 作用域等概念的支撑，例如 `suspernd main` ，有限考虑通过 `coroutineScope` 创建作用域

## join 和 await

前面的例子一直是用 `launch` 启动协程常用的还有 `async`, `actor` `produce` 其中 `actor` 和 `launch` 的行为类似，在未捕获异常出现以后，会抛出。而 `async` 和 `produce` 则主要是用来输出结果的，它们内部的异常只在外部消费他们的记过时才抛出。

### 什么是消费结果

两组协程启动器，我们可以分别认为是 *消费者* 和 *生产者* 

消费者异常立即抛出；生产者只有结果异常时抛出

### **async 和 await**

```kotlin
suspend fun main() {
    val deferred = GlobalScope.async<Int> {
        throw ArithmeticException()
    }
    try {
        val value = deferred.await()
        log("1. $value")
    } catch (e: Exception) {
        log("2. $e")
    }
}
```

当我们调用 `await` 时，期望 `deferred` 能够给我们一个合适的结果，但是它发生了异常，没有办法左到， 随后就抛出一个异常给我们

```tex
2. java.lang.ArithmeticException
```

### join

`join` 则和 `await` 不同， `join` 只关心是否执行完，至于为什么完成，它不关心。将上面的 `await` 替换成 `join` 后 

```tex
1. kotlin.Unit
```

异常信息被吞掉了，用 `launch` 替换 `async` ，`join` 处仍然不会有任何响应。

`launch` 中未捕获的异常与 `aysync` 的处理方式不同， `launch` 会直接抛出异常给父协程，如果没有父协程或者处于 `supervisorScope` 中父协程不响应，那么就会交给上下文中执行的 `CoroutineExceptionHandler` 处理，如果没有指定，那就传给全局的 `CoroutineExcetionHandler` 等等。而 `async`  则要等 `await` 来消费